<?xml version="1.0" ?>
<sdf version="1.8">
    <world name="car_world">



        <physics name="1ms" type="ignored">
            <max_step_size>0.001</max_step_size>
            <real_time_factor>1.0</real_time_factor>
        </physics>
        <plugin
            filename="libignition-gazebo-physics-system.so"
            name="ignition::gazebo::systems::Physics">
        </plugin>
        <plugin
            filename="libignition-gazebo-user-commands-system.so"
            name="ignition::gazebo::systems::UserCommands">
        </plugin>
        <plugin
            filename="libignition-gazebo-scene-broadcaster-system.so"
            name="ignition::gazebo::systems::SceneBroadcaster">
        </plugin>
        <plugin filename="ignition-gazebo-imu-system"
                name="ignition::gazebo::systems::Imu">
        </plugin>
        <plugin filename="ignition-gazebo-sensors-system"
                name="ignition::gazebo::systems::Sensors">
            <render_engine>ogre2</render_engine>
        </plugin>
        <plugin filename="ignition-gazebo-contact-system"
                name="ignition::gazebo::systems::Contact">
        </plugin>


        <light type="directional" name="sun">
            <cast_shadows>true</cast_shadows>
            <pose>0 0 10 0 0 0</pose>
            <diffuse>0.8 0.8 0.8 1</diffuse>
            <specular>0.2 0.2 0.2 1</specular>
            <attenuation>
                <range>1000</range>
                <constant>0.9</constant>
                <linear>0.01</linear>
                <quadratic>0.001</quadratic>
            </attenuation>
            <direction>-0.5 0.1 -0.9</direction>
        </light>

        <model name="ground_plane">
            <static>true</static>
            <link name="link">
                <collision name="collision">
                <geometry>
                    <plane>
                    <normal>0 0 1</normal>
                    </plane>
                </geometry>
                </collision>
                <visual name="visual">
                <geometry>
                    <plane>
                    <normal>0 0 1</normal>
                    <size>100 100</size>
                    </plane>
                </geometry>
                <material>
                    <ambient>0.8 0.8 0.8 1</ambient>
                    <diffuse>0.8 0.8 0.8 1</diffuse>
                    <specular>0.8 0.8 0.8 1</specular>
                </material>
                </visual>
            </link>
        </model>

        <!-- 加载 SDF 模型 -->

  <model name='bipedal_4'>
  <pose>0 0 0.3 0 0 0</pose>
    <link name='base_link'>
      <inertial>
        <pose>-0.013974 0.00114 0.15072 0 -0 0</pose>
        <mass>19.0171</mass>
        <inertia>
          <ixx>0.0677121</ixx>
          <ixy>-2.15982e-06</ixy>
          <ixz>0.00156576</ixz>
          <iyy>0.0792221</iyy>
          <iyz>1.06848e-05</iyz>
          <izz>0.0827647</izz>
        </inertia>
      </inertial>
      <collision name='base_link_collision'>
        <pose>0 0 -0.01 0 0 0</pose>
        <geometry>
          <mesh>
            <scale>1 1 1</scale>
            <uri>model://bipedal_4/meshes/base_link.STL</uri>
          </mesh>
        </geometry>
      </collision>
      <visual name='base_link_visual'>
        <pose>0 0 0 0 -0 0</pose>
        <geometry>
          <mesh>
            <scale>1 1 1</scale>
            <uri>model://bipedal_4/meshes/base_link.STL</uri>
          </mesh>
        </geometry>
        <material>
          <ambient>0.3 0.3 0.3 1</ambient> 
          <diffuse>0.6 0.6 0.6 1</diffuse>  
          <specular>0.2 0.2 0.2 1</specular> 
        </material>
      </visual>
    </link>
    <joint name='Lbig_joint' type='revolute'>
      <pose relative_to='base_link'>-0.000178 0.167799 0.141513 0 -0 0</pose>
      <parent>base_link</parent>
      <child>Lbig_Link</child>
      <axis>
        <xyz>0 1 0</xyz>
        <limit>
          <lower>-60</lower>
          <upper>20</upper>
          <effort>10</effort>
          <velocity>10</velocity>
        </limit>
        <dynamics>
          <spring_reference>0</spring_reference>
          <spring_stiffness>0</spring_stiffness>
        </dynamics>
      </axis>
    </joint>
    <link name='Lbig_Link'>
      <pose relative_to='Lbig_joint'>0 0 0 0 -0 0</pose>
      <inertial>
        <pose>-0.09915 0.010957 -0.007039 0 -0 0</pose>
        <mass>0.279663</mass>
        <inertia>
          <ixx>9.5839e-05</ixx>
          <ixy>1.88655e-06</ixy>
          <ixz>-6.77181e-05</ixz>
          <iyy>0.00152349</iyy>
          <iyz>-5.34323e-07</iyz>
          <izz>0.00143434</izz>
        </inertia>
      </inertial>
      <collision name='Lbig_Link_collision'>
        <pose>0 0 0 0 -0 0</pose>
        <geometry>
          <mesh>
            <scale>1 1 1</scale>
            <uri>model://bipedal_4/meshes/Lbig_Link.STL</uri>
          </mesh>
        </geometry>
      </collision>
      <visual name='Lbig_Link_visual'>
        <pose>0 0 0 0 -0 0</pose>
        <geometry>
          <mesh>
            <scale>1 1 1</scale>
            <uri>model://bipedal_4/meshes/Lbig_Link.STL</uri>
          </mesh>
        </geometry>
        <material>
          <ambient>0.3 0.3 0.3 1</ambient> 
          <diffuse>0.6 0.6 0.6 1</diffuse>  
          <specular>0.2 0.2 0.2 1</specular> 
        </material>
      </visual>
    </link>
    <joint name='Lsmall_joint' type='revolute'>
      <pose relative_to='Lbig_Link'>-0.214311 0.021 -0.017197 0 -0 0</pose>
      <parent>Lbig_Link</parent>
      <child>Lsmall_Link</child>
      <axis>
        <xyz>0 1 0</xyz>
        <limit>
          <lower>-2.1</lower>
          <upper>60.0</upper>
          <effort>10</effort>
          <velocity>10</velocity>
        </limit>
        <dynamics>
          <spring_reference>0</spring_reference>
          <spring_stiffness>0</spring_stiffness>
        </dynamics>
      </axis>
    </joint>
    <link name='Lsmall_Link'>
      <pose relative_to='Lsmall_joint'>0 0 0 0 -0 0</pose>
      <inertial>
        <pose>0.079592 0.007638 -0.04948 0 -0 0</pose>
        <mass>0.280241</mass>
        <inertia>
          <ixx>0.000573834</ixx>
          <ixy>-1.08614e-06</ixy>
          <ixz>0.000768878</ixz>
          <iyy>0.00188519</iyy>
          <iyz>1.54955e-06</iyz>
          <izz>0.00132472</izz>
        </inertia>
      </inertial>
      <collision name='Lsmall_Link_collision'>
        <pose>0 0 0 0 -0 0</pose>
        <geometry>
          <mesh>
            <scale>1 1 1</scale>
            <uri>model://bipedal_4/meshes/Lsmall_Link.STL</uri>
          </mesh>
        </geometry>
      </collision>
      <visual name='Lsmall_Link_visual'>
        <pose>0 0 0 0 -0 0</pose>
        <geometry>
          <mesh>
            <scale>1 1 1</scale>
            <uri>model://bipedal_4/meshes/Lsmall_Link.STL</uri>
          </mesh>
        </geometry>
        <material>
          <ambient>0.3 0.3 0.3 1</ambient> 
          <diffuse>0.6 0.6 0.6 1</diffuse>  
          <specular>0.2 0.2 0.2 1</specular> 
        </material>
      </visual>
    </link>
    <joint name='Lwheel_joint' type='revolute'>
      <pose relative_to='Lsmall_Link'>0.216526 0.02955 -0.132787 0 -0 0</pose>
      <parent>Lsmall_Link</parent>
      <child>Lwheel_Link</child>
      <axis>
        <xyz>0 1 0</xyz>
        <limit>
          <lower>-1.79769e+308</lower>
          <upper>1.79769e+308</upper>
          <effort>10</effort>
          <velocity>10</velocity>
        </limit>
        <dynamics>
          <spring_reference>0</spring_reference>
          <spring_stiffness>0</spring_stiffness>
        </dynamics>
      </axis>
    </joint>
    <link name='Lwheel_Link'>
      <pose relative_to='Lwheel_joint'>0 0 0 0 -0 0</pose>
      <inertial>
        <pose>5.1e-05 -0.003049 -9.3e-05 0 -0 0</pose>
        <mass>0.304045</mass>
        <inertia>
          <ixx>0.000308809</ixx>
          <ixy>1.34202e-07</ixy>
          <ixz>-3.59301e-07</ixz>
          <iyy>0.000569585</iyy>
          <iyz>-2.0098e-07</iyz>
          <izz>0.000309114</izz>
        </inertia>
      </inertial>
      <collision name='Lwheel_Link_collision'>
        <pose>0 0 0 0 -0 0</pose>
        <geometry>
          <mesh>
            <scale>1 1 1</scale>
            <uri>model://bipedal_4/meshes/Lwheel_Link.STL</uri>
          </mesh>
        </geometry>
      </collision>
      <visual name='Lwheel_Link_visual'>
        <pose>0 0 0 0 -0 0</pose>
        <geometry>
          <mesh>
            <scale>1 1 1</scale>
            <uri>model://bipedal_4/meshes/Lwheel_Link.STL</uri>
          </mesh>
        </geometry>
        <material>
          <ambient>0.2 0.2 0.2 1</ambient>
          <diffuse>0.2 0.2 0.2 1</diffuse>
          <specular>0.5 0.5 0.5 1</specular>
        </material>
      </visual>
    </link>
    <joint name='Rbig_joint' type='revolute'>
      <pose relative_to='base_link'>-0.000178 -0.163201 0.141513 0 -0 0</pose>
      <parent>base_link</parent>
      <child>Rbig_Link</child>
      <axis>
        <xyz>0 -1 0</xyz>
        <limit>
          <lower>-20</lower>
          <upper>60</upper>
          <effort>10</effort>
          <velocity>10</velocity>
        </limit>
        <dynamics>
          <spring_reference>0</spring_reference>
          <spring_stiffness>0</spring_stiffness>
        </dynamics>
      </axis>
    </joint>
    <link name='Rbig_Link'>
      <pose relative_to='Rbig_joint'>0 0 0 0 -0 0</pose>
      <inertial>
        <pose>-0.098958 -0.010875 0.001169 0 -0 0</pose>
        <mass>0.273515</mass>
        <inertia>
          <ixx>9.28253e-05</ixx>
          <ixy>-1.82687e-06</ixy>
          <ixz>4.2679e-05</ixz>
          <iyy>0.00151102</iyy>
          <iyz>6.82543e-07</iyz>
          <izz>0.00142474</izz>
        </inertia>
      </inertial>
      <collision name='Rbig_Link_collision'>
        <pose>0 0 0 0 -0 0</pose>
        <geometry>
          <mesh>
            <scale>1 1 1</scale>
            <uri>model://bipedal_4/meshes/Rbig_Link.STL</uri>
          </mesh>
        </geometry>
      </collision>
      <visual name='Rbig_Link_visual'>
        <pose>0 0 0 0 -0 0</pose>
        <geometry>
          <mesh>
            <scale>1 1 1</scale>
            <uri>model://bipedal_4/meshes/Rbig_Link.STL</uri>
          </mesh>
        </geometry>
        <material>
          <ambient>0.3 0.3 0.3 1</ambient> 
          <diffuse>0.6 0.6 0.6 1</diffuse>  
          <specular>0.2 0.2 0.2 1</specular> 
        </material>
      </visual>
    </link>
    <joint name='Rsmall_joint' type='revolute'>
      <pose relative_to='Rbig_Link'>-0.214999 -0.021 0.000489 0 -0 0</pose>
      <parent>Rbig_Link</parent>
      <child>Rsmall_Link</child>
      <axis>
        <xyz>0 -1 0</xyz>
        <limit>
          <lower>-60</lower>
          <upper>2.1</upper>
          <effort>10</effort>
          <velocity>10</velocity>
        </limit>
        <dynamics>
          <spring_reference>0</spring_reference>
          <spring_stiffness>0</spring_stiffness>
        </dynamics>
      </axis>
    </joint>
    <link name='Rsmall_Link'>
      <pose relative_to='Rsmall_joint'>0 0 0 0 -0 0</pose>
      <inertial>
        <pose>0.088576 -0.007215 -0.055792 0 -0 0</pose>
        <mass>0.251916</mass>
        <inertia>
          <ixx>0.000569012</ixx>
          <ixy>1.18974e-06</ixy>
          <ixz>0.000768613</ixz>
          <iyy>0.00187798</iyy>
          <iyz>-1.26065e-06</iyz>
          <izz>0.00132225</izz>
        </inertia>
      </inertial>
      <collision name='Rsmall_Link_collision'>
        <pose>0 0 0 0 -0 0</pose>
        <geometry>
          <mesh>
            <scale>1 1 1</scale>
            <uri>model://bipedal_4/meshes/Rsmall_Link.STL</uri>
          </mesh>
        </geometry>
      </collision>
      <visual name='Rsmall_Link_visual'>
        <pose>0 0 0 0 -0 0</pose>
        <geometry>
          <mesh>
            <scale>1 1 1</scale>
            <uri>model://bipedal_4/meshes/Rsmall_Link.STL</uri>
          </mesh>
        </geometry>
        <material>
          <ambient>0.3 0.3 0.3 1</ambient> 
          <diffuse>0.6 0.6 0.6 1</diffuse>  
          <specular>0.2 0.2 0.2 1</specular> 
        </material>
      </visual>
    </link>


    <joint name='Rwheel_joint' type='revolute'>
      <pose relative_to='Rsmall_Link'>0.214846 -0.02955 -0.135489 0 -0 0</pose>
      <parent>Rsmall_Link</parent>
      <child>Rwheel_Link</child>
      <axis>
        <xyz expressed_in='__model__'>0 -1 0</xyz>
        <limit>
          <lower>-1.79769e+308</lower>
          <upper>1.79769e+308</upper>
          <effort>10</effort>
          <velocity>10</velocity>
        </limit>
        <dynamics>
          <spring_reference>0</spring_reference>
          <spring_stiffness>0</spring_stiffness>
        </dynamics>
      </axis>
    </joint>

    <link name='Rwheel_Link'>
      <pose relative_to='Rwheel_joint'>0 0 0 0 -0 0</pose>
      <inertial>
        <pose>0.000106 0.003049 -4e-06 0 -0 0</pose>
        <mass>0.304045</mass>
        <inertia>
          <ixx>0.00030934</ixx>
          <ixy>-2.39606e-07</ixy>
          <ixz>-9.77394e-08</ixz>
          <iyy>0.000569585</iyy>
          <iyz>3.14965e-08</iyz>
          <izz>0.000308584</izz>
        </inertia>
      </inertial>
      <collision name='Rwheel_Link_collision'>
        <pose>0 0 0 0 -0 0</pose>
        <geometry>
          <mesh>
            <scale>1 1 1</scale>
            <uri>model://bipedal_4/meshes/Rwheel_Link.STL</uri>
          </mesh>
        </geometry>
      </collision>
      <visual name='Rwheel_Link_visual'>
        <pose>0 0 0 0 -0 0</pose>
        <geometry>
          <mesh>
            <scale>1 1 1</scale>
            <uri>model://bipedal_4/meshes/Rwheel_Link.STL</uri>
          </mesh>
        </geometry>
        <material>
          <ambient>0.2 0.2 0.2 1</ambient>
          <diffuse>0.2 0.2 0.2 1</diffuse>
          <specular>0.5 0.5 0.5 1</specular>
        </material>
      </visual>
    </link>

    <!-- Add joint controller plugin-->
    <plugin
        filename="libignition-gazebo6-joint-controller-system.so"
        name="ignition::gazebo::systems::JointController">
        <topic>/cmd_vel</topic>
        <joint_name>Rwheel_joint</joint_name>
        <initial_velocity>-5.0</initial_velocity> 
    </plugin>

    <plugin
        filename="libignition-gazebo6-joint-controller-system.so"
        name="ignition::gazebo::systems::JointController">
        <topic>/cmd_vel</topic>
        <joint_name>Lwheel_joint</joint_name>
        <initial_velocity>5.0</initial_velocity>
    </plugin>

    <plugin
        filename="libignition-gazebo6-joint-controller-system.so"
        name="ignition::gazebo::systems::JointController">
        <topic>/cmd_vel</topic>
        <joint_name>Lbig_joint</joint_name>
        <initial_velocity>-5.0</initial_velocity> 
    </plugin>

    <plugin
        filename="libignition-gazebo6-joint-controller-system.so"
        name="ignition::gazebo::systems::JointController">
        <topic>/cmd_vel</topic>
        <joint_name>Lsmall_joint</joint_name>
        <initial_velocity>5.0</initial_velocity>
    </plugin>

    <plugin
        filename="libignition-gazebo6-joint-controller-system.so"
        name="ignition::gazebo::systems::JointController">
        <topic>/cmd_vel</topic>
        <joint_name>Rbig_joint</joint_name>
        <initial_velocity>-5.0</initial_velocity> 
    </plugin>

    <plugin
        filename="libignition-gazebo6-joint-controller-system.so"
        name="ignition::gazebo::systems::JointController">
        <topic>/cmd_vel</topic>
        <joint_name>Rsmall_joint</joint_name>
        <initial_velocity>5.0</initial_velocity>
    </plugin>


  </model>







    </world>
</sdf>

